Workbook

Sheet TEAM INFO
A1: Team Name | B1: Shortened | C1: Player Name | D1: Player Position | E1: Detailed
A2: O2 Blast | B2: O2
C3: FATE | D3: TANK
C4: SEUNGAN | D4: TANK
C5: WUTIAN | D5: DPS | E5: FLEX DPS
C6: PERR | D6: DPS | E6: MAIN DPS
C7: FAITH | D7: SPT | E7: MAN SPT
C8: MISIN | D8: SPT | E8: FLEX SPT
C9: GAMJUNG | D9: SPT | E9: FLEX SPT
A10: Røde Zanside Gaming | B10: ROZE
C11: VOID | D11: TANK
C12: HEISER | D12: TANK
C13: BECKY | D13: DPS | E13: FLEX DPS
C14: KILO | D14: DPS | E14: MAIN DPS
C15: PROBE | D15: DPS | E15: MAIN DPS
C16: OPENER | D16: SPT | E16: MAIN SPT
C17: IRONY | D17: SPT | E17: FLEX SPT
A18: Cheeseburger | B18: CB
C19: FARMER | D19: TANK
C20: GUR3UM | D20: TANK
C21: ARGON | D21: DPS | E21: FLEX DPS
C22: M1NUT2 | D22: DPS | E22: MAIN DPS
C23: TENTEN | D23: SPT | E23: MAIN SPT
C24: WOOCHAN | D24: SPT | E24: FLEX SPT
A25: Poker Face | B25: PF
C26: FEARFUL | D26: TANK
C27: HYEON | D27: TANK
C28: D0D0 | D28: DPS | E28: FLEX DPS
C29: K4NE | D29: DPS | E29: MAIN DPS
C30: SP1NEL | D30: SPT | E30: MAIN SPT
C31: CARU | D31: SPT | E31: FLEX SPT
A32: ZETA DIVISION | B32: ZETA
C33: MEALGARU | D33: TANK
C34: BERNAR | D34: TANK
C35: PROPER | D35: DPS | E35: FLEX DPS
C36: KNIFE | D36: DPS | E36: MAIN DPS
C37: VIOL2T | D37: SPT | E37: MAIN SPT
C38: SHU | D38: SPT | E38: FLEX SPT
A39: Crazy Raccoon | B39: CR
C40: JUNBIN | D40: TANK
...

Sheet MATCH INFO
A1: WEEK | B1: DAY | C1: MATCH | D1: Set # | E1: DATE | F1: PHASE | G1: TEAM 1 | H1: TEAM 2 | I1: MAP | J1: MAP TYPE | K1: TIME | L1: WINNER | M1: TEAM 1 BAN | N1: TEAM 2 BAN | O1: MATCH_ID | P1: TEAM 1 SCORE | Q1: TEAM 2 SCORE | R1: INITIAL BAN RIGHT | S1: INITIAL BAN
A2: 1 | B2: 1 | C2: 1 | D2: 1 | E2: 46178 | F2: Round Robin | G2: O2 | H2: ROZE | I2: Ilios | J2: =IF(OR(I2="Antarctic Peninsula", I2="Nepal", I2="Lijiang Tower", I2="Busan", I2="Samoa", I2="Oasis", I2="Ilios"), "Control", IF(OR(I2="Route 66", I2="Watchpoint: Gibraltar", I2="Dorado", I2="Rialto", I2="Shambali Monastery", I2="Circuit Royal", I2="Junkertown", I2="Havana"), "Escort", IF(OR(I2="Neon Junction", I2="Numbani", I2="Midtown", I2="Blizzard World", I2="Eichenwalde", I2="King's Row", I2="Paraiso", I2="Hollywood"), "Hybrid", IF(OR(I2="New Queen Street", I2="Esperanca", I2="Colosseo", I2="Runasapi"), "Push", IF(OR(I2="New Junk City", I2="Suravasa", I2="Aatlis"), "Flashpoint", ""))))) -> Control | K2: 0.0067013889 | L2: O2 | M2: D.Va | N2: Jetpack Cat | O2: =TEXT(E2, "yymmdd") & "_" & G2 & "_" & H2 & "_S" & D2 -> 260605_O2_ROZE_S1 | P2: 2 | Q2: 0 | R2: TEAM 1 | S2: D.Va
A3: 1 | B3: 1 | C3: 1 | D3: 2 | E3: 46178 | F3: Round Robin | G3: O2 | H3: ROZE | I3: Suravasa | J3: =IF(OR(I3="Antarctic Peninsula", I3="Nepal", I3="Lijiang Tower", I3="Busan", I3="Samoa", I3="Oasis", I3="Ilios"), "Control", IF(OR(I3="Route 66", I3="Watchpoint: Gibraltar", I3="Dorado", I3="Rialto", I3="Shambali Monastery", I3="Circuit Royal", I3="Junkertown", I3="Havana"), "Escort", IF(OR(I3="Neon Junction", I3="Numbani", I3="Midtown", I3="Blizzard World", I3="Eichenwalde", I3="King's Row", I3="Paraiso", I3="Hollywood"), "Hybrid", IF(OR(I3="New Queen Street", I3="Esperanca", I3="Colosseo", I3="Runasapi"), "Push", IF(OR(I3="New Junk City", I3="Suravasa", I3="Aatlis"), "Flashpoint", ""))))) -> Flashpoint | K3: 0.010416667 | L3: O2 | M3: Symmetra | N3: Domina | O3: =TEXT(E3, "yymmdd") & "_" & G3 & "_" & H3 & "_S" & D3 -> 260605_O2_ROZE_S2 | P3: 3 | Q3: 2 | R3: TEAM 1 | S3: Symmetra
A4: 1 | B4: 1 | C4: 1 | D4: 3 | E4: 46178 | F4: Round Robin | G4: O2 | H4: ROZE | I4: Runasapi | J4: =IF(OR(I4="Antarctic Peninsula", I4="Nepal", I4="Lijiang Tower", I4="Busan", I4="Samoa", I4="Oasis", I4="Ilios"), "Control", IF(OR(I4="Route 66", I4="Watchpoint: Gibraltar", I4="Dorado", I4="Rialto", I4="Shambali Monastery", I4="Circuit Royal", I4="Junkertown", I4="Havana"), "Escort", IF(OR(I4="Neon Junction", I4="Numbani", I4="Midtown", I4="Blizzard World", I4="Eichenwalde", I4="King's Row", I4="Paraiso", I4="Hollywood"), "Hybrid", IF(OR(I4="New Queen Street", I4="Esperanca", I4="Colosseo", I4="Runasapi"), "Push", IF(OR(I4="New Junk City", I4="Suravasa", I4="Aatlis"), "Flashpoint", ""))))) -> Push | K4: 0.0074074074 | L4: O2 | M4: Lucio | N4: Pharah | O4: =TEXT(E4, "yymmdd") & "_" & G4 & "_" & H4 & "_S" & D4 -> 260605_O2_ROZE_S3 | P4: 125.66 | Q4: 72.02 | R4: TEAM 2 | S4: Pharah
A5: 1 | B5: 1 | C5: 2 | D5: 1 | E5: 46178 | F5: Round Robin | G5: FLC | H5: CR | I5: Antarctic Peninsula | J5: =IF(OR(I5="Antarctic Peninsula", I5="Nepal", I5="Lijiang Tower", I5="Busan", I5="Samoa", I5="Oasis", I5="Ilios"), "Control", IF(OR(I5="Route 66", I5="Watchpoint: Gibraltar", I5="Dorado", I5="Rialto", I5="Shambali Monastery", I5="Circuit Royal", I5="Junkertown", I5="Havana"), "Escort", IF(OR(I5="Neon Junction", I5="Numbani", I5="Midtown", I5="Blizzard World", I5="Eichenwalde", I5="King's Row", I5="Paraiso", I5="Hollywood"), "Hybrid", IF(OR(I5="New Queen Street", I5="Esperanca", I5="Colosseo", I5="Runasapi"), "Push", IF(OR(I5="New Junk City", I5="Suravasa", I5="Aatlis"), "Flashpoint", ""))))) -> Control | K5: 0.0052083333 | L5: CR | M5: Mei | N5: Reinhardt | O5: =TEXT(E5, "yymmdd") & "_" & G5 & "_" & H5 & "_S" & D5 -> 260605_FLC_CR_S1 | P5: 2 | Q5: 0 | R5: TEAM 1 | S5: Sigma
A6: 1 | B6: 1 | C6: 2 | D6: 2 | E6: 46178 | F6: Round Robin | G6: FLC | H6: CR | I6: King's Row | J6: =IF(OR(I6="Antarctic Peninsula", I6="Nepal", I6="Lijiang Tower", I6="Busan", I6="Samoa", I6="Oasis", I6="Ilios"), "Control", IF(OR(I6="Route 66", I6="Watchpoint: Gibraltar", I6="Dorado", I6="Rialto", I6="Shambali Monastery", I6="Circuit Royal", I6="Junkertown", I6="Havana"), "Escort", IF(OR(I6="Neon Junction", I6="Numbani", I6="Midtown", I6="Blizzard World", I6="Eichenwalde", I6="King's Row", I6="Paraiso", I6="Hollywood"), "Hybrid", IF(OR(I6="New Queen Street", I6="Esperanca", I6="Colosseo", I6="Runasapi"), "Push", IF(OR(I6="New Junk City", I6="Suravasa", I6="Aatlis"), "Flashpoint", ""))))) -> Hybrid | K6: 0.0097800926 | L6: CR | M6: Pharah | N6: Lucio | O6: =TEXT(E6, "yymmdd") & "_" & G6 & "_" & H6 & "_S" & D6 -> 260605_FLC_CR_S2 | P6: 1 | Q6: 2 | R6: TEAM 1 | S6: Bastion
A7: 1 | B7: 1 | C7: 2 | D7: 3 | E7: 46178 | F7: Round Robin | G7: FLC | H7: CR | I7: New Queen Street | J7: =IF(OR(I7="Antarctic Peninsula", I7="Nepal", I7="Lijiang Tower", I7="Busan", I7="Samoa", I7="Oasis", I7="Ilios"), "Control", IF(OR(I7="Route 66", I7="Watchpoint: Gibraltar", I7="Dorado", I7="Rialto", I7="Shambali Monastery", I7="Circuit Royal", I7="Junkertown", I7="Havana"), "Escort", IF(OR(I7="Neon Junction", I7="Numbani", I7="Midtown", I7="Blizzard World", I7="Eichenwalde", I7="King's Row", I7="Paraiso", I7="Hollywood"), "Hybrid", IF(OR(I7="New Queen Street", I7="Esperanca", I7="Colosseo", I7="Runasapi"), "Push", IF(OR(I7="New Junk City", I7="Suravasa", I7="Aatlis"), "Flashpoint", ""))))) -> Push | K7: 0.0071643519 | L7: CR | M7: Wrecking Ball | N7: Bastion | O7: =TEXT(E7, "yymmdd") & "_" & G7 & "_" & H7 & "_S" & D7 -> 260605_FLC_CR_S3 | P7: 105.91 | Q7: 106.08 | R7: TEAM 1 | S7: Wrecking Ball
A8: 1 | B8: 1 | C8: 3 | D8: 1 | E8: 46178 | F8: Round Robin | G8: T1 | H8: ZETA | I8: Antarctic Peninsula | J8: =IF(OR(I8="Antarctic Peninsula", I8="Nepal", I8="Lijiang Tower", I8="Busan", I8="Samoa", I8="Oasis", I8="Ilios"), "Control", IF(OR(I8="Route 66", I8="Watchpoint: Gibraltar", I8="Dorado", I8="Rialto", I8="Shambali Monastery", I8="Circuit Royal", I8="Junkertown", I8="Havana"), "Escort", IF(OR(I8="Neon Junction", I8="Numbani", I8="Midtown", I8="Blizzard World", I8="Eichenwalde", I8="King's Row", I8="Paraiso", I8="Hollywood"), "Hybrid", IF(OR(I8="New Queen Street", I8="Esperanca", I8="Colosseo", I8="Runasapi"), "Push", IF(OR(I8="New Junk City", I8="Suravasa", I8="Aatlis"), "Flashpoint", ""))))) -> Control | K8: 0.0058449074 | L8: T1 | M8: Jetpack Cat | N8: Reinhardt | O8: =TEXT(E8, "yymmdd") & "_" & G8 & "_" & H8 & "_S" & D8 -> 260605_T1_ZETA_S1 | P8: 0 | Q8: 2 | R8: TEAM 1 | S8: Jetpack Cat
A9: 1 | B9: 1 | C9: 3 | D9: 2 | E9: 46178 | F9: Round Robin | G9: T1 | H9: ZETA | I9: Rialto | J9: =IF(OR(I9="Antarctic Peninsula", I9="Nepal", I9="Lijiang Tower", I9="Busan", I9="Samoa", I9="Oasis", I9="Ilios"), "Control", IF(OR(I9="Route 66", I9="Watchpoint: Gibraltar", I9="Dorado", I9="Rialto", I9="Shambali Monastery", I9="Circuit Royal", I9="Junkertown", I9="Havana"), "Escort", IF(OR(I9="Neon Junction", I9="Numbani", I9="Midtown", I9="Blizzard World", I9="Eichenwalde", I9="King's Row", I9="Paraiso", I9="Hollywood"), "Hybrid", IF(OR(I9="New Queen Street", I9="Esperanca", I9="Colosseo", I9="Runasapi"), "Push", IF(OR(I9="New Junk City", I9="Suravasa", I9="Aatlis"), "Flashpoint", ""))))) -> Escort | K9: 0.010671296 | L9: ZETA | M9: D.Va | N9: Lucio | O9: =TEXT(E9, "yymmdd") & "_" & G9 & "_" & H9 & "_S" & D9 -> 260605_T1_ZETA_S2 | P9: 1 | Q9: 2 | R9: TEAM 2 | S9: Lucio
A10: 1 | B10: 1 | C10: 3 | D10: 3 | E10: 46178 | F10: Round Robin | G10: T1 | H10: ZETA | I10: New Junk City | J10: =IF(OR(I10="Antarctic Peninsula", I10="Nepal", I10="Lijiang Tower", I10="Busan", I10="Samoa", I10="Oasis", I10="Ilios"), "Control", IF(OR(I10="Route 66", I10="Watchpoint: Gibraltar", I10="Dorado", I10="Rialto", I10="Shambali Monastery", I10="Circuit Royal", I10="Junkertown", I10="Havana"), "Escort", IF(OR(I10="Neon Junction", I10="Numbani", I10="Midtown", I10="Blizzard World", I10="Eichenwalde", I10="King's Row", I10="Paraiso", I10="Hollywood"), "Hybrid", IF(OR(I10="New Queen Street", I10="Esperanca", I10="Colosseo", I10="Runasapi"), "Push", IF(OR(I10="New Junk City", I10="Suravasa", I10="Aatlis"), "Flashpoint", ""))))) -> Flashpoint | K10: 0.0053125 | L10: T1 | M10: Cassidy | N10: Mauga | O10: =TEXT(E10, "yymmdd") & "_" & G10 & "_" & H10 & "_S" & D10 -> 260605_T1_ZETA_S3 | P10: 3 | Q10: 2 | R10: TEAM 2 | S10: Vendetta
A11: 1 | B11: 1 | C11: 3 | D11: 4 | E11: 46178 | F11: Round Robin | G11: T1 | H11: ZETA | I11: King's Row | J11: =IF(OR(I11="Antarctic Peninsula", I11="Nepal", I11="Lijiang Tower", I11="Busan", I11="Samoa", I11="Oasis", I11="Ilios"), "Control", IF(OR(I11="Route 66", I11="Watchpoint: Gibraltar", I11="Dorado", I11="Rialto", I11="Shambali Monastery", I11="Circuit Royal", I11="Junkertown", I11="Havana"), "Escort", IF(OR(I11="Neon Junction", I11="Numbani", I11="Midtown", I11="Blizzard World", I11="Eichenwalde", I11="King's Row", I11="Paraiso", I11="Hollywood"), "Hybrid", IF(OR(I11="New Queen Street", I11="Esperanca", I11="Colosseo", I11="Runasapi"), "Push", IF(OR(I11="New Junk City", I11="Suravasa", I11="Aatlis"), "Flashpoint", ""))))) -> Hybrid | K11: 0.011342593 | L11: ZETA | M11: Pharah | N11: Kiriko | O11: =TEXT(E11, "yymmdd") & "_" & G11 & "_" & H11 & "_S" & D11 -> 260605_T1_ZETA_S4 | P11: 3 | Q11: 4 | R11: TEAM 2 | S11: Kiriko
A12: 1 | B12: 1 | C12: 3 | D12: 5 | E12: 46178 | F12: Round Robin | G12: T1 | H12: ZETA | I12: Runasapi | J12: =IF(OR(I12="Antarctic Peninsula", I12="Nepal", I12="Lijiang Tower", I12="Busan", I12="Samoa", I12="Oasis", I12="Ilios"), "Control", IF(OR(I12="Route 66", I12="Watchpoint: Gibraltar", I12="Dorado", I12="Rialto", I12="Shambali Monastery", I12="Circuit Royal", I12="Junkertown", I12="Havana"), "Escort", IF(OR(I12="Neon Junction", I12="Numbani", I12="Midtown", I12="Blizzard World", I12="Eichenwalde", I12="King's Row", I12="Paraiso", I12="Hollywood"), "Hybrid", IF(OR(I12="New Queen Street", I12="Esperanca", I12="Colosseo", I12="Runasapi"), "Push", IF(OR(I12="New Junk City", I12="Suravasa", I12="Aatlis"), "Flashpoint", ""))))) -> Push | K12: 0.007337963 | L12: T1 | M12: Bastion | N12: Zarya | O12: =TEXT(E12, "yymmdd") & "_" & G12 & "_" & H12 & "_S" & D12 -> 260605_T1_ZETA_S5 | P12: 73.6 | Q12: 57.99 | R12: TEAM 1 | S12: Bastion
A13: 1 | B13: 2 | C13: 1 | D13: 1 | E13: 46179 | F13: Round Robin | G13: PF | H13: CB | I13: Antarctic Peninsula | J13: =IF(OR(I13="Antarctic Peninsula", I13="Nepal", I13="Lijiang Tower", I13="Busan", I13="Samoa", I13="Oasis", I13="Ilios"), "Control", IF(OR(I13="Route 66", I13="Watchpoint: Gibraltar", I13="Dorado", I13="Rialto", I13="Shambali Monastery", I13="Circuit Royal", I13="Junkertown", I13="Havana"), "Escort", IF(OR(I13="Neon Junction", I13="Numbani", I13="Midtown", I13="Blizzard World", I13="Eichenwalde", I13="King's Row", I13="Paraiso", I13="Hollywood"), "Hybrid", IF(OR(I13="New Queen Street", I13="Esperanca", I13="Colosseo", I13="Runasapi"), "Push", IF(OR(I13="New Junk City", I13="Suravasa", I13="Aatlis"), "Flashpoint", ""))))) -> Control | L13: CB | M13: Bastion | N13: Juno | O13: =TEXT(E13, "yymmdd") & "_" & G13 & "_" & H13 & "_S" & D13 -> 260606_PF_CB_S1 | P13: 0 | Q13: 2 | R13: TEAM 1 | S13: Bastion
A14: 1 | B14: 2 | C14: 1 | D14: 2 | E14: 46179 | F14: Round Robin | G14: PF | H14: CB | I14: Suravasa | J14: =IF(OR(I14="Antarctic Peninsula", I14="Nepal", I14="Lijiang Tower", I14="Busan", I14="Samoa", I14="Oasis", I14="Ilios"), "Control", IF(OR(I14="Route 66", I14="Watchpoint: Gibraltar", I14="Dorado", I14="Rialto", I14="Shambali Monastery", I14="Circuit Royal", I14="Junkertown", I14="Havana"), "Escort", IF(OR(I14="Neon Junction", I14="Numbani", I14="Midtown", I14="Blizzard World", I14="Eichenwalde", I14="King's Row", I14="Paraiso", I14="Hollywood"), "Hybrid", IF(OR(I14="New Queen Street", I14="Esperanca", I14="Colosseo", I14="Runasapi"), "Push", IF(OR(I14="New Junk City", I14="Suravasa", I14="Aatlis"), "Flashpoint", ""))))) -> Flashpoint | L14: CB | M14: Jetpack Cat | N14: Pharah | O14: =TEXT(E14, "yymmdd") & "_" & G14 & "_" & H14 & "_S" & D14 -> 260606_PF_CB_S2 | P14: 2 | Q14: 3 | R14: TEAM 1 | S14: Jetpack Cat
A15: 1 | B15: 2 | C15: 1 | D15: 3 | E15: 46179 | F15: Round Robin | G15: PF | H15: CB | I15: Runasapi | J15: =IF(OR(I15="Antarctic Peninsula", I15="Nepal", I15="Lijiang Tower", I15="Busan", I15="Samoa", I15="Oasis", I15="Ilios"), "Control", IF(OR(I15="Route 66", I15="Watchpoint: Gibraltar", I15="Dorado", I15="Rialto", I15="Shambali Monastery", I15="Circuit Royal", I15="Junkertown", I15="Havana"), "Escort", IF(OR(I15="Neon Junction", I15="Numbani", I15="Midtown", I15="Blizzard World", I15="Eichenwalde", I15="King's Row", I15="Paraiso", I15="Hollywood"), "Hybrid", IF(OR(I15="New Queen Street", I15="Esperanca", I15="Colosseo", I15="Runasapi"), "Push", IF(OR(I15="New Junk City", I15="Suravasa", I15="Aatlis"), "Flashpoint", ""))))) -> Push | L15: CB | M15: Sigma | N15: Cassidy | O15: =TEXT(E15, "yymmdd") & "_" & G15 & "_" & H15 & "_S" & D15 -> 260606_PF_CB_S3 | P15: 0 | Q15: 144.86 | R15: TEAM 1 | S15: Sigma
A16: 1 | B16: 2 | C16: 2 | D16: 1 | E16: 46179 | F16: Round Robin | G16: T1 | H16: SB | I16: Oasis | J16: =IF(OR(I16="Antarctic Peninsula", I16="Nepal", I16="Lijiang Tower", I16="Busan", I16="Samoa", I16="Oasis", I16="Ilios"), "Control", IF(OR(I16="Route 66", I16="Watchpoint: Gibraltar", I16="Dorado", I16="Rialto", I16="Shambali Monastery", I16="Circuit Royal", I16="Junkertown", I16="Havana"), "Escort", IF(OR(I16="Neon Junction", I16="Numbani", I16="Midtown", I16="Blizzard World", I16="Eichenwalde", I16="King's Row", I16="Paraiso", I16="Hollywood"), "Hybrid", IF(OR(I16="New Queen Street", I16="Esperanca", I16="Colosseo", I16="Runasapi"), "Push", IF(OR(I16="New Junk City", I16="Suravasa", I16="Aatlis"), "Flashpoint", ""))))) -> Control | L16: T1 | M16: Roadhog | N16: Cassidy | O16: =TEXT(E16, "yymmdd") & "_" & G16 & "_" & H16 & "_S" & D16 -> 260606_T1_SB_S1 | P16: 2 | Q16: 0 | R16: TEAM 1 | S16: Roadhog
A17: 1 | B17: 2 | C17: 2 | D17: 2 | E17: 46179 | F17: Round Robin | G17: T1 | H17: SB | I17: Numbani | J17: =IF(OR(I17="Antarctic Peninsula", I17="Nepal", I17="Lijiang Tower", I17="Busan", I17="Samoa", I17="Oasis", I17="Ilios"), "Control", IF(OR(I17="Route 66", I17="Watchpoint: Gibraltar", I17="Dorado", I17="Rialto", I17="Shambali Monastery", I17="Circuit Royal", I17="Junkertown", I17="Havana"), "Escort", IF(OR(I17="Neon Junction", I17="Numbani", I17="Midtown", I17="Blizzard World", I17="Eichenwalde", I17="King's Row", I17="Paraiso", I17="Hollywood"), "Hybrid", IF(OR(I17="New Queen Street", I17="Esperanca", I17="Colosseo", I17="Runasapi"), "Push", IF(OR(I17="New Junk City", I17="Suravasa", I17="Aatlis"), "Flashpoint", ""))))) -> Hybrid | L17: T1 | M17: Illari | N17: Pharah | O17: =TEXT(E17, "yymmdd") & "_" & G17 & "_" & H17 & "_S" & D17 -> 260606_T1_SB_S2 | P17: 3 | Q17: 1 | R17: TEAM 2 | S17: Pharah
A18: 1 | B18: 2 | C18: 2 | D18: 3 | E18: 46179 | F18: Round Robin | G18: T1 | H18: SB | I18: New Junk City | J18: =IF(OR(I18="Antarctic Peninsula", I18="Nepal", I18="Lijiang Tower", I18="Busan", I18="Samoa", I18="Oasis", I18="Ilios"), "Control", IF(OR(I18="Route 66", I18="Watchpoint: Gibraltar", I18="Dorado", I18="Rialto", I18="Shambali Monastery", I18="Circuit Royal", I18="Junkertown", I18="Havana"), "Escort", IF(OR(I18="Neon Junction", I18="Numbani", I18="Midtown", I18="Blizzard World", I18="Eichenwalde", I18="King's Row", I18="Paraiso", I18="Hollywood"), "Hybrid", IF(OR(I18="New Queen Street", I18="Esperanca", I18="Colosseo", I18="Runasapi"), "Push", IF(OR(I18="New Junk City", I18="Suravasa", I18="Aatlis"), "Flashpoint", ""))))) -> Flashpoint | L18: T1 | M18: Mauga | N18: Mizuki | O18: =TEXT(E18, "yymmdd") & "_" & G18 & "_" & H18 & "_S" & D18 -> 260606_T1_SB_S3 | P18: 3 | Q18: 0 | R18: TEAM 2 | S18: Mizuki
A19: 1 | B19: 2 | C19: 3 | D19: 1 | E19: 46179 | F19: Round Robin | G19: ROZE | H19: FLC | I19: Oasis | J19: =IF(OR(I19="Antarctic Peninsula", I19="Nepal", I19="Lijiang Tower", I19="Busan", I19="Samoa", I19="Oasis", I19="Ilios"), "Control", IF(OR(I19="Route 66", I19="Watchpoint: Gibraltar", I19="Dorado", I19="Rialto", I19="Shambali Monastery", I19="Circuit Royal", I19="Junkertown", I19="Havana"), "Escort", IF(OR(I19="Neon Junction", I19="Numbani", I19="Midtown", I19="Blizzard World", I19="Eichenwalde", I19="King's Row", I19="Paraiso", I19="Hollywood"), "Hybrid", IF(OR(I19="New Queen Street", I19="Esperanca", I19="Colosseo", I19="Runasapi"), "Push", IF(OR(I19="New Junk City", I19="Suravasa", I19="Aatlis"), "Flashpoint", ""))))) -> Control | L19: FLC | M19: Pharah | N19: Sigma | O19: =TEXT(E19, "yymmdd") & "_" & G19 & "_" & H19 & "_S" & D19 -> 260606_ROZE_FLC_S1 | P19: 0 | Q19: 2 | R19: TEAM 2 | S19: Sigma
A20: 1 | B20: 2 | C20: 3 | D20: 2 | E20: 46179 | F20: Round Robin | G20: ROZE | H20: FLC | I20: Suravasa | J20: =IF(OR(I20="Antarctic Peninsula", I20="Nepal", I20="Lijiang Tower", I20="Busan", I20="Samoa", I20="Oasis", I20="Ilios"), "Control", IF(OR(I20="Route 66", I20="Watchpoint: Gibraltar", I20="Dorado", I20="Rialto", I20="Shambali Monastery", I20="Circuit Royal", I20="Junkertown", I20="Havana"), "Escort", IF(OR(I20="Neon Junction", I20="Numbani", I20="Midtown", I20="Blizzard World", I20="Eichenwalde", I20="King's Row", I20="Paraiso", I20="Hollywood"), "Hybrid", IF(OR(I20="New Queen Street", I20="Esperanca", I20="Colosseo", I20="Runasapi"), "Push", IF(OR(I20="New Junk City", I20="Suravasa", I20="Aatlis"), "Flashpoint", ""))))) -> Flashpoint | L20: FLC | M20: Bastion | N20: Mizuki | O20: =TEXT(E20, "yymmdd") & "_" & G20 & "_" & H20 & "_S" & D20 -> 260606_ROZE_FLC_S2 | P20: 1 | Q20: 3 | R20: TEAM 1 | S20: Bastion
A21: 1 | B21: 2 | C21: 3 | D21: 3 | E21: 46179 | F21: Round Robin | G21: ROZE | H21: FLC | I21: Runasapi | J21: =IF(OR(I21="Antarctic Peninsula", I21="Nepal", I21="Lijiang Tower", I21="Busan", I21="Samoa", I21="Oasis", I21="Ilios"), "Control", IF(OR(I21="Route 66", I21="Watchpoint: Gibraltar", I21="Dorado", I21="Rialto", I21="Shambali Monastery", I21="Circuit Royal", I21="Junkertown", I21="Havana"), "Escort", IF(OR(I21="Neon Junction", I21="Numbani", I21="Midtown", I21="Blizzard World", I21="Eichenwalde", I21="King's Row", I21="Paraiso", I21="Hollywood"), "Hybrid", IF(OR(I21="New Queen Street", I21="Esperanca", I21="Colosseo", I21="Runasapi"), "Push", IF(OR(I21="New Junk City", I21="Suravasa", I21="Aatlis"), "Flashpoint", ""))))) -> Push | L21: FLC | M21: Jetpack Cat | N21: Bastion | O21: =TEXT(E21, "yymmdd") & "_" & G21 & "_" & H21 & "_S" & D21 -> 260606_ROZE_FLC_S3 | P21: 77.47 | Q21: 130.65 | R21: TEAM 1 | S21: Jetpack Cat
A22: 1 | B22: 3 | C22: 1 | D22: 1 | E22: 46180 | F22: Round Robin | G22: SB | H22: O2 | I22: Oasis | J22: =IF(OR(I22="Antarctic Peninsula", I22="Nepal", I22="Lijiang Tower", I22="Busan", I22="Samoa", I22="Oasis", I22="Ilios"), "Control", IF(OR(I22="Route 66", I22="Watchpoint: Gibraltar", I22="Dorado", I22="Rialto", I22="Shambali Monastery", I22="Circuit Royal", I22="Junkertown", I22="Havana"), "Escort", IF(OR(I22="Neon Junction", I22="Numbani", I22="Midtown", I22="Blizzard World", I22="Eichenwalde", I22="King's Row", I22="Paraiso", I22="Hollywood"), "Hybrid", IF(OR(I22="New Queen Street", I22="Esperanca", I22="Colosseo", I22="Runasapi"), "Push", IF(OR(I22="New Junk City", I22="Suravasa", I22="Aatlis"), "Flashpoint", ""))))) -> Control | L22: O2 | M22: Sojourn | N22: Lucio | O22: =TEXT(E22, "yymmdd") & "_" & G22 & "_" & H22 & "_S" & D22 -> 260607_SB_O2_S1 | P22: 1 | Q22: 2 | R22: TEAM 1 | S22: Sojourn
A23: 1 | B23: 3 | C23: 1 | D23: 2 | E23: 46180 | F23: Round Robin | G23: SB | H23: O2 | I23: Rialto | J23: =IF(OR(I23="Antarctic Peninsula", I23="Nepal", I23="Lijiang Tower", I23="Busan", I23="Samoa", I23="Oasis", I23="Ilios"), "Control", IF(OR(I23="Route 66", I23="Watchpoint: Gibraltar", I23="Dorado", I23="Rialto", I23="Shambali Monastery", I23="Circuit Royal", I23="Junkertown", I23="Havana"), "Escort", IF(OR(I23="Neon Junction", I23="Numbani", I23="Midtown", I23="Blizzard World", I23="Eichenwalde", I23="King's Row", I23="Paraiso", I23="Hollywood"), "Hybrid", IF(OR(I23="New Queen Street", I23="Esperanca", I23="Colosseo", I23="Runasapi"), "Push", IF(OR(I23="New Junk City", I23="Suravasa", I23="Aatlis"), "Flashpoint", ""))))) -> Escort | L23: O2 | M23: Ana | N23: Zarya | O23: =TEXT(E23, "yymmdd") & "_" & G23 & "_" & H23 & "_S" & D23 -> 260607_SB_O2_S2 | P23: 0 | Q23: 2 | R23: TEAM 1 | S23: Ana
A24: 1 | B24: 3 | C24: 1 | D24: 3 | E24: 46180 | F24: Round Robin | G24: SB | H24: O2 | I24: Hollywood | J24: =IF(OR(I24="Antarctic Peninsula", I24="Nepal", I24="Lijiang Tower", I24="Busan", I24="Samoa", I24="Oasis", I24="Ilios"), "Control", IF(OR(I24="Route 66", I24="Watchpoint: Gibraltar", I24="Dorado", I24="Rialto", I24="Shambali Monastery", I24="Circuit Royal", I24="Junkertown", I24="Havana"), "Escort", IF(OR(I24="Neon Junction", I24="Numbani", I24="Midtown", I24="Blizzard World", I24="Eichenwalde", I24="King's Row", I24="Paraiso", I24="Hollywood"), "Hybrid", IF(OR(I24="New Queen Street", I24="Esperanca", I24="Colosseo", I24="Runasapi"), "Push", IF(OR(I24="New Junk City", I24="Suravasa", I24="Aatlis"), "Flashpoint", ""))))) -> Hybrid | L24: O2 | M24: Tracer | N24: Reinhardt | O24: =TEXT(E24, "yymmdd") & "_" & G24 & "_" & H24 & "_S" & D24 -> 260607_SB_O2_S3 | P24: 1 | Q24: 2 | R24: TEAM 1 | S24: Tracer
... A136: 5 | B136: 2 | C136: 1 | D136: 1 | E136: 46207 | F136: LCQ | G136: CB | H136: SB | I136: Nepal | J136: =IF(OR(I136="Antarctic Peninsula", I136="Nepal", I136="Lijiang Tower", I136="Busan", I136="Samoa", I136="Oasis", I136="Ilios"), "Control", IF(OR(I136="Route 66", I136="Watchpoint: Gibraltar", I136="Dorado", I136="Rialto", I136="Shambali Monastery", I136="Circuit Royal", I136="Junkertown", I136="Havana"), "Escort", IF(OR(I136="Neon Junction", I136="Numbani", I136="Midtown", I136="Blizzard World", I136="Eichenwalde", I136="King's Row", I136="Paraiso", I136="Hollywood"), "Hybrid", IF(OR(I136="New Queen Street", I136="Esperanca", I136="Colosseo", I136="Runasapi"), "Push", IF(OR(I136="New Junk City", I136="Suravasa", I136="Aatlis"), "Flashpoint", ""))))) -> Control | L136: CB | M136: Sigma | N136: Bastion | O136: =TEXT(E136, "yymmdd") & "_" & G136 & "_" & H136 & "_S" & D136 -> 260704_CB_SB_S1 | P136: 2 | Q136: 0 | R136: TEAM 1 | S136: Sigma
A137: 5 | B137: 2 | C137: 1 | D137: 2 | E137: 46207 | F137: LCQ | G137: CB | H137: SB | I137: Aatlis | J137: =IF(OR(I137="Antarctic Peninsula", I137="Nepal", I137="Lijiang Tower", I137="Busan", I137="Samoa", I137="Oasis", I137="Ilios"), "Control", IF(OR(I137="Route 66", I137="Watchpoint: Gibraltar", I137="Dorado", I137="Rialto", I137="Shambali Monastery", I137="Circuit Royal", I137="Junkertown", I137="Havana"), "Escort", IF(OR(I137="Neon Junction", I137="Numbani", I137="Midtown", I137="Blizzard World", I137="Eichenwalde", I137="King's Row", I137="Paraiso", I137="Hollywood"), "Hybrid", IF(OR(I137="New Queen Street", I137="Esperanca", I137="Colosseo", I137="Runasapi"), "Push", IF(OR(I137="New Junk City", I137="Suravasa", I137="Aatlis"), "Flashpoint", ""))))) -> Flashpoint | L137: CB | M137: Mizuki | N137: Shion | O137: =TEXT(E137, "yymmdd") & "_" & G137 & "_" & H137 & "_S" & D137 -> 260704_CB_SB_S2
A138: 5 | B138: 2 | C138: 1 | D138: 3 | E138: 46207 | F138: LCQ | G138: CB | H138: SB | I138: Neon Junction | J138: =IF(OR(I138="Antarctic Peninsula", I138="Nepal", I138="Lijiang Tower", I138="Busan", I138="Samoa", I138="Oasis", I138="Ilios"), "Control", IF(OR(I138="Route 66", I138="Watchpoint: Gibraltar", I138="Dorado", I138="Rialto", I138="Shambali Monastery", I138="Circuit Royal", I138="Junkertown", I138="Havana"), "Escort", IF(OR(I138="Neon Junction", I138="Numbani", I138="Midtown", I138="Blizzard World", I138="Eichenwalde", I138="King's Row", I138="Paraiso", I138="Hollywood"), "Hybrid", IF(OR(I138="New Queen Street", I138="Esperanca", I138="Colosseo", I138="Runasapi"), "Push", IF(OR(I138="New Junk City", I138="Suravasa", I138="Aatlis"), "Flashpoint", ""))))) -> Hybrid | L138: CB | M138: Cassidy | N138: Zarya | O138: =TEXT(E138, "yymmdd") & "_" & G138 & "_" & H138 & "_S" & D138 -> 260704_CB_SB_S3 | P138: 3 | Q138: 1 | R138: TEAM 2 | S138: Zarya
A139: 5 | B139: 2 | C139: 2 | D139: 1 | E139: 46207 | F139: 2nd RR | G139: CR | H139: T1 | I139: Antarctic Peninsula | J139: =IF(OR(I139="Antarctic Peninsula", I139="Nepal", I139="Lijiang Tower", I139="Busan", I139="Samoa", I139="Oasis", I139="Ilios"), "Control", IF(OR(I139="Route 66", I139="Watchpoint: Gibraltar", I139="Dorado", I139="Rialto", I139="Shambali Monastery", I139="Circuit Royal", I139="Junkertown", I139="Havana"), "Escort", IF(OR(I139="Neon Junction", I139="Numbani", I139="Midtown", I139="Blizzard World", I139="Eichenwalde", I139="King's Row", I139="Paraiso", I139="Hollywood"), "Hybrid", IF(OR(I139="New Queen Street", I139="Esperanca", I139="Colosseo", I139="Runasapi"), "Push", IF(OR(I139="New Junk City", I139="Suravasa", I139="Aatlis"), "Flashpoint", ""))))) -> Control | L139: T1 | M139: Roadhog | N139: Jetpack Cat | O139: =TEXT(E139, "yymmdd") & "_" & G139 & "_" & H139 & "_S" & D139 -> 260704_CR_T1_S1 | P139: 0 | Q139: 2 | R139: TEAM 2 | S139: Jetpack Cat
A140: 5 | B140: 2 | C140: 2 | D140: 2 | E140: 46207 | F140: 2nd RR | G140: CR | H140: T1 | I140: Circuit Royal | J140: =IF(OR(I140="Antarctic Peninsula", I140="Nepal", I140="Lijiang Tower", I140="Busan", I140="Samoa", I140="Oasis", I140="Ilios"), "Control", IF(OR(I140="Route 66", I140="Watchpoint: Gibraltar", I140="Dorado", I140="Rialto", I140="Shambali Monastery", I140="Circuit Royal", I140="Junkertown", I140="Havana"), "Escort", IF(OR(I140="Neon Junction", I140="Numbani", I140="Midtown", I140="Blizzard World", I140="Eichenwalde", I140="King's Row", I140="Paraiso", I140="Hollywood"), "Hybrid", IF(OR(I140="New Queen Street", I140="Esperanca", I140="Colosseo", I140="Runasapi"), "Push", IF(OR(I140="New Junk City", I140="Suravasa", I140="Aatlis"), "Flashpoint", ""))))) -> Escort | L140: CR | M140: Illari | N140: Sierra | O140: =TEXT(E140, "yymmdd") & "_" & G140 & "_" & H140 & "_S" & D140 -> 260704_CR_T1_S2 | P140: 3 | Q140: 2 | R140: TEAM 2 | S140: Sierra
A141: 5 | B141: 2 | C141: 2 | D141: 3 | E141: 46207 | F141: 2nd RR | G141: CR | H141: T1 | I141: New Junk City | J141: =IF(OR(I141="Antarctic Peninsula", I141="Nepal", I141="Lijiang Tower", I141="Busan", I141="Samoa", I141="Oasis", I141="Ilios"), "Control", IF(OR(I141="Route 66", I141="Watchpoint: Gibraltar", I141="Dorado", I141="Rialto", I141="Shambali Monastery", I141="Circuit Royal", I141="Junkertown", I141="Havana"), "Escort", IF(OR(I141="Neon Junction", I141="Numbani", I141="Midtown", I141="Blizzard World", I141="Eichenwalde", I141="King's Row", I141="Paraiso", I141="Hollywood"), "Hybrid", IF(OR(I141="New Queen Street", I141="Esperanca", I141="Colosseo", I141="Runasapi"), "Push", IF(OR(I141="New Junk City", I141="Suravasa", I141="Aatlis"), "Flashpoint", ""))))) -> Flashpoint | L141: CR | M141: Vendetta | N141: D.Va | O141: =TEXT(E141, "yymmdd") & "_" & G141 & "_" & H141 & "_S" & D141 -> 260704_CR_T1_S3 | P141: 3 | Q141: 2 | R141: TEAM 1 | S141: Vendetta
A142: 5 | B142: 2 | C142: 2 | D142: 4 | E142: 46207 | F142: 2nd RR | G142: CR | H142: T1 | I142: Hollywood | J142: =IF(OR(I142="Antarctic Peninsula", I142="Nepal", I142="Lijiang Tower", I142="Busan", I142="Samoa", I142="Oasis", I142="Ilios"), "Control", IF(OR(I142="Route 66", I142="Watchpoint: Gibraltar", I142="Dorado", I142="Rialto", I142="Shambali Monastery", I142="Circuit Royal", I142="Junkertown", I142="Havana"), "Escort", IF(OR(I142="Neon Junction", I142="Numbani", I142="Midtown", I142="Blizzard World", I142="Eichenwalde", I142="King's Row", I142="Paraiso", I142="Hollywood"), "Hybrid", IF(OR(I142="New Queen Street", I142="Esperanca", I142="Colosseo", I142="Runasapi"), "Push", IF(OR(I142="New Junk City", I142="Suravasa", I142="Aatlis"), "Flashpoint", ""))))) -> Hybrid | L142: CR | M142: Bastion | N142: Mauga | O142: =TEXT(E142, "yymmdd") & "_" & G142 & "_" & H142 & "_S" & D142 -> 260704_CR_T1_S4 | P142: 4 | Q142: 3 | R142: TEAM 2 | S142: Bastion
A143: 5 | B143: 2 | C143: 3 | D143: 1 | E143: 46207 | F143: 2nd RR | G143: ZETA | H143: FLC | I143: Ilios | J143: =IF(OR(I143="Antarctic Peninsula", I143="Nepal", I143="Lijiang Tower", I143="Busan", I143="Samoa", I143="Oasis", I143="Ilios"), "Control", IF(OR(I143="Route 66", I143="Watchpoint: Gibraltar", I143="Dorado", I143="Rialto", I143="Shambali Monastery", I143="Circuit Royal", I143="Junkertown", I143="Havana"), "Escort", IF(OR(I143="Neon Junction", I143="Numbani", I143="Midtown", I143="Blizzard World", I143="Eichenwalde", I143="King's Row", I143="Paraiso", I143="Hollywood"), "Hybrid", IF(OR(I143="New Queen Street", I143="Esperanca", I143="Colosseo", I143="Runasapi"), "Push", IF(OR(I143="New Junk City", I143="Suravasa", I143="Aatlis"), "Flashpoint", ""))))) -> Control | L143: FLC | M143: D.Va | N143: Bastion | O143: =TEXT(E143, "yymmdd") & "_" & G143 & "_" & H143 & "_S" & D143 -> 260704_ZETA_FLC_S1 | P143: 1 | Q143: 2 | R143: TEAM 1 | S143: D.Va
A144: 5 | B144: 2 | C144: 3 | D144: 2 | E144: 46207 | F144: 2nd RR | G144: ZETA | H144: FLC | I144: King's Row | J144: =IF(OR(I144="Antarctic Peninsula", I144="Nepal", I144="Lijiang Tower", I144="Busan", I144="Samoa", I144="Oasis", I144="Ilios"), "Control", IF(OR(I144="Route 66", I144="Watchpoint: Gibraltar", I144="Dorado", I144="Rialto", I144="Shambali Monastery", I144="Circuit Royal", I144="Junkertown", I144="Havana"), "Escort", IF(OR(I144="Neon Junction", I144="Numbani", I144="Midtown", I144="Blizzard World", I144="Eichenwalde", I144="King's Row", I144="Paraiso", I144="Hollywood"), "Hybrid", IF(OR(I144="New Queen Street", I144="Esperanca", I144="Colosseo", I144="Runasapi"), "Push", IF(OR(I144="New Junk City", I144="Suravasa", I144="Aatlis"), "Flashpoint", ""))))) -> Hybrid | L144: ZETA | M144: Reinhardt | N144: Mizuki | O144: =TEXT(E144, "yymmdd") & "_" & G144 & "_" & H144 & "_S" & D144 -> 260704_ZETA_FLC_S2 | P144: 3 | Q144: 2 | R144: TEAM 1 | S144: Reinhardt
A145: 5 | B145: 2 | C145: 3 | D145: 3 | E145: 46207 | F145: 2nd RR | G145: ZETA | H145: FLC | I145: Colosseo | J145: =IF(OR(I145="Antarctic Peninsula", I145="Nepal", I145="Lijiang Tower", I145="Busan", I145="Samoa", I145="Oasis", I145="Ilios"), "Control", IF(OR(I145="Route 66", I145="Watchpoint: Gibraltar", I145="Dorado", I145="Rialto", I145="Shambali Monastery", I145="Circuit Royal", I145="Junkertown", I145="Havana"), "Escort", IF(OR(I145="Neon Junction", I145="Numbani", I145="Midtown", I145="Blizzard World", I145="Eichenwalde", I145="King's Row", I145="Paraiso", I145="Hollywood"), "Hybrid", IF(OR(I145="New Queen Street", I145="Esperanca", I145="Colosseo", I145="Runasapi"), "Push", IF(OR(I145="New Junk City", I145="Suravasa", I145="Aatlis"), "Flashpoint", ""))))) -> Push | L145: ZETA | M145: Symmetra | N145: Zarya | O145: =TEXT(E145, "yymmdd") & "_" & G145 & "_" & H145 & "_S" & D145 -> 260704_ZETA_FLC_S3 | P145: 108.72 | Q145: 108.71 | R145: TEAM 2 | S145: Zarya
A146: 5 | B146: 2 | C146: 3 | D146: 4 | E146: 46207 | F146: 2nd RR | G146: ZETA | H146: FLC | I146: Circuit Royal | J146: =IF(OR(I146="Antarctic Peninsula", I146="Nepal", I146="Lijiang Tower", I146="Busan", I146="Samoa", I146="Oasis", I146="Ilios"), "Control", IF(OR(I146="Route 66", I146="Watchpoint: Gibraltar", I146="Dorado", I146="Rialto", I146="Shambali Monastery", I146="Circuit Royal", I146="Junkertown", I146="Havana"), "Escort", IF(OR(I146="Neon Junction", I146="Numbani", I146="Midtown", I146="Blizzard World", I146="Eichenwalde", I146="King's Row", I146="Paraiso", I146="Hollywood"), "Hybrid", IF(OR(I146="New Queen Street", I146="Esperanca", I146="Colosseo", I146="Runasapi"), "Push", IF(OR(I146="New Junk City", I146="Suravasa", I146="Aatlis"), "Flashpoint", ""))))) -> Escort | L146: FLC | M146: Sigma | N146: Jetpack Cat | O146: =TEXT(E146, "yymmdd") & "_" & G146 & "_" & H146 & "_S" & D146 -> 260704_ZETA_FLC_S4 | P146: 2 | Q146: 3 | R146: TEAM 2 | S146: Jetpack Cat
A147: 5 | B147: 2 | C147: 3 | D147: 5 | E147: 46207 | F147: 2nd RR | G147: ZETA | H147: FLC | I147: New Junk City | J147: =IF(OR(I147="Antarctic Peninsula", I147="Nepal", I147="Lijiang Tower", I147="Busan", I147="Samoa", I147="Oasis", I147="Ilios"), "Control", IF(OR(I147="Route 66", I147="Watchpoint: Gibraltar", I147="Dorado", I147="Rialto", I147="Shambali Monastery", I147="Circuit Royal", I147="Junkertown", I147="Havana"), "Escort", IF(OR(I147="Neon Junction", I147="Numbani", I147="Midtown", I147="Blizzard World", I147="Eichenwalde", I147="King's Row", I147="Paraiso", I147="Hollywood"), "Hybrid", IF(OR(I147="New Queen Street", I147="Esperanca", I147="Colosseo", I147="Runasapi"), "Push", IF(OR(I147="New Junk City", I147="Suravasa", I147="Aatlis"), "Flashpoint", ""))))) -> Flashpoint | L147: ZETA | M147: Lucio | N147: D.Va | O147: =TEXT(E147, "yymmdd") & "_" & G147 & "_" & H147 & "_S" & D147 -> 260704_ZETA_FLC_S5 | P147: 3 | Q147: 0 | R147: TEAM 1 | S147: Lucio
A148: 5 | B148: 3 | C148: 1 | D148: 1 | E148: 46208 | F148: LCQ | G148: O2 | H148: CB | I148: Antarctic Peninsula | J148: =IF(OR(I148="Antarctic Peninsula", I148="Nepal", I148="Lijiang Tower", I148="Busan", I148="Samoa", I148="Oasis", I148="Ilios"), "Control", IF(OR(I148="Route 66", I148="Watchpoint: Gibraltar", I148="Dorado", I148="Rialto", I148="Shambali Monastery", I148="Circuit Royal", I148="Junkertown", I148="Havana"), "Escort", IF(OR(I148="Neon Junction", I148="Numbani", I148="Midtown", I148="Blizzard World", I148="Eichenwalde", I148="King's Row", I148="Paraiso", I148="Hollywood"), "Hybrid", IF(OR(I148="New Queen Street", I148="Esperanca", I148="Colosseo", I148="Runasapi"), "Push", IF(OR(I148="New Junk City", I148="Suravasa", I148="Aatlis"), "Flashpoint", ""))))) -> Control | L148: O2 | M148: D.Va | N148: Lucio | O148: =TEXT(E148, "yymmdd") & "_" & G148 & "_" & H148 & "_S" & D148 -> 260705_O2_CB_S1 | P148: 2 | Q148: 1 | R148: TEAM 1 | S148: D.Va
A149: 5 | B149: 3 | C149: 1 | D149: 2 | E149: 46208 | F149: LCQ | G149: O2 | H149: CB | I149: Neon Junction | J149: =IF(OR(I149="Antarctic Peninsula", I149="Nepal", I149="Lijiang Tower", I149="Busan", I149="Samoa", I149="Oasis", I149="Ilios"), "Control", IF(OR(I149="Route 66", I149="Watchpoint: Gibraltar", I149="Dorado", I149="Rialto", I149="Shambali Monastery", I149="Circuit Royal", I149="Junkertown", I149="Havana"), "Escort", IF(OR(I149="Neon Junction", I149="Numbani", I149="Midtown", I149="Blizzard World", I149="Eichenwalde", I149="King's Row", I149="Paraiso", I149="Hollywood"), "Hybrid", IF(OR(I149="New Queen Street", I149="Esperanca", I149="Colosseo", I149="Runasapi"), "Push", IF(OR(I149="New Junk City", I149="Suravasa", I149="Aatlis"), "Flashpoint", ""))))) -> Hybrid | L149: Cb | M149: Mauga | N149: Mizuki | O149: =TEXT(E149, "yymmdd") & "_" & G149 & "_" & H149 & "_S" & D149 -> 260705_O2_CB_S2 | P149: 1 | Q149: 2 | R149: TEAM 2 | S149: Mizuki
... A189: 6 | B189: 3 | C189: 2 | D189: 6 | E189: 46215 | F189: Playoffs | G189: CR | H189: ZETA | I189: Neon Junction | J189: =IF(OR(I189="Antarctic Peninsula", I189="Nepal", I189="Lijiang Tower", I189="Busan", I189="Samoa", I189="Oasis", I189="Ilios"), "Control", IF(OR(I189="Route 66", I189="Watchpoint: Gibraltar", I189="Dorado", I189="Rialto", I189="Shambali Monastery", I189="Circuit Royal", I189="Junkertown", I189="Havana"), "Escort", IF(OR(I189="Neon Junction", I189="Numbani", I189="Midtown", I189="Blizzard World", I189="Eichenwalde", I189="King's Row", I189="Paraiso", I189="Hollywood"), "Hybrid", IF(OR(I189="New Queen Street", I189="Esperanca", I189="Colosseo", I189="Runasapi"), "Push", IF(OR(I189="New Junk City", I189="Suravasa", I189="Aatlis"), "Flashpoint", ""))))) -> Hybrid | L189: ZETA | M189: Domina | N189: Mei | O189: =TEXT(E189, "yymmdd") & "_" & G189 & "_" & H189 & "_S" & D189 -> 260712_CR_ZETA_S6 | P189: 4 | Q189: 5 | R189: TEAM 1 | S189: Domina

Sheet MATCH_W1
A1: Team | B1: Player | C1: Position | D1: Map | E1: Map Type | F1: Elim | G1: Death | H1: Assists | I1: Damage | J1: Heal | K1: Mitigated | L1: Playtime | M1: Playtime(Seconds) | N1: MATCH_ID
A2: O2 | B2: FATE | C2: TANK | D2: Ilios | E2: Control | F2: 22 | G2: 2 | H2: 5 | I2: 6120 | J2: 1714 | K2: 4420 | L2: 00:09:39 | M2: =L2*86400 -> 579 | N2: {=INDEX('MATCH INFO'!O:O, INT((ROW()-2)/10)+2)} -> 260605_O2_ROZE_S1
A3: O2 | B3: WUTIAN | C3: DPS | D3: Ilios | E3: Control | F3: 23 | G3: 3 | H3: 4 | I3: 10396 | J3: 60 | K3: 0 | L3: 00:09:39 | M3: =L3*86400 -> 579 | N3: {=INDEX('MATCH INFO'!O:O, INT((ROW()-2)/10)+2)} -> 260605_O2_ROZE_S1
A4: O2 | B4: PERR | C4: DPS | D4: Ilios | E4: Control | F4: 25 | G4: 2 | H4: 0 | I4: 10213 | J4: 0 | K4: 0 | L4: 00:09:39 | M4: =L4*86400 -> 579 | N4: {=INDEX('MATCH INFO'!O:O, INT((ROW()-2)/10)+2)} -> 260605_O2_ROZE_S1
A5: O2 | B5: FAITH | C5: SPT | D5: Ilios | E5: Control | F5: 12 | G5: 4 | H5: 18 | I5: 3677 | J5: 6457 | K5: 3491 | L5: 00:09:39 | M5: =L5*86400 -> 579 | N5: {=INDEX('MATCH INFO'!O:O, INT((ROW()-2)/10)+2)} -> 260605_O2_ROZE_S1
A6: O2 | B6: MISIN | C6: SPT | D6: Ilios | E6: Control | F6: 12 | G6: 17 | H6: 5 | I6: 3185 | J6: 6147 | K6: 469 | L6: 00:09:39 | M6: =L6*86400 -> 579 | N6: {=INDEX('MATCH INFO'!O:O, INT((ROW()-2)/10)+2)} -> 260605_O2_ROZE_S1
A7: ROZE | B7: VOID | C7: TANK | D7: Ilios | E7: Control | F7: 8 | G7: 8 | H7: 5 | I7: 6686 | J7: 686 | K7: 3654 | L7: 00:09:39 | M7: =L7*86400 -> 579 | N7: {=INDEX('MATCH INFO'!O:O, INT((ROW()-2)/10)+2)} -> 260605_O2_ROZE_S1
A8: ROZE | B8: BECKY | C8: DPS | D8: Ilios | E8: Control | F8: 10 | G8: 6 | H8: 1 | I8: 6624 | J8: 220 | K8: 933 | L8: 00:09:39 | M8: =L8*86400 -> 579 | N8: {=INDEX('MATCH INFO'!O:O, INT((ROW()-2)/10)+2)} -> 260605_O2_ROZE_S1
A9: ROZE | B9: KILO | C9: DPS | D9: Ilios | E9: Control | F9: 10 | G9: 9 | H9: 0 | I9: 9396 | J9: 244 | K9: 142 | L9: 00:09:39 | M9: =L9*86400 -> 579 | N9: {=INDEX('MATCH INFO'!O:O, INT((ROW()-2)/10)+2)} -> 260605_O2_ROZE_S1
A10: ROZE | B10: OPENER | C10: SPT | D10: Ilios | E10: Control | F10: 5 | G10: 6 | H10: 11 | I10: 2641 | J10: 6350 | K10: 600 | L10: 00:09:39 | M10: =L10*86400 -> 579 | N10: {=INDEX('MATCH INFO'!O:O, INT((ROW()-2)/10)+2)} -> 260605_O2_ROZE_S1
A11: ROZE | B11: IRONY | C11: SPT | D11: Ilios | E11: Control | F11: 4 | G11: 7 | H11: 13 | I11: 3521 | J11: 9034 | K11: 0 | L11: 00:09:39 | M11: =L11*86400 -> 579 | N11: {=INDEX('MATCH INFO'!O:O, INT((ROW()-2)/10)+2)} -> 260605_O2_ROZE_S1
A12: O2 | B12: SEUNGAN | C12: TANK | D12: Suravasa | E12: Flashpoint | F12: 20 | G12: 5 | H12: 2 | I12: 15181 | J12: 0 | K12: 31167 | L12: 00:15:00 | M12: =L12*86400 -> 900 | N12: {=INDEX('MATCH INFO'!O:O, INT((ROW()-2)/10)+2)} -> 260605_O2_ROZE_S2
A13: O2 | B13: WUTIAN | C13: DPS | D13: Suravasa | E13: Flashpoint | F13: 17 | G13: 7 | H13: 0 | I13: 10272 | J13: 165 | K13: 0 | L13: 00:15:00 | M13: =L13*86400 -> 900 | N13: {=INDEX('MATCH INFO'!O:O, INT((ROW()-2)/10)+2)} -> 260605_O2_ROZE_S2
... A291: CR | B291: VIGILANTE | C291: SPT | D291: Runasapi | E291: Push | F291: 20 | G291: 5 | H291: 17 | I291: 9535 | J291: 2481 | K291: 593 | L291: 00:10:31 | M291: =L291*86400 -> 631 | N291: {=INDEX('MATCH INFO'!O:O, INT((ROW()-2)/10)+2)} -> 260607_CR_PF_S3

Sheet MATCH_W2
A1: Team | B1: Player | C1: Position | D1: Map | E1: Map Type | F1: Elim | G1: Death | H1: Assists | I1: Damage | J1: Heal | K1: Mitigated | L1: Playtime | M1: Playtime(Seconds) | N1: MATCH_ID
A2: CB | B2: ARGON | C2: DPS | D2: Ilios | E2: Control | F2: 13 | G2: 1 | H2: 0 | I2: 6715 | J2: 958 | K2: 0 | L2: 00:07:06 | M2: =L2*86400 -> 426 | N2: {=INDEX('MATCH INFO'!O:O, INT((ROW()-2)/10)+2 + 29)} -> 260612_CB_SB_S1
A3: CB | B3: FARMER | C3: TANK | D3: Ilios | E3: Control | F3: 15 | G3: 2 | H3: 3 | I3: 5418 | J3: 3101 | K3: 2770 | L3: 00:07:06 | M3: =L3*86400 -> 426 | N3: {=INDEX('MATCH INFO'!O:O, INT((ROW()-2)/10)+2 + 29)} -> 260612_CB_SB_S1
A4: CB | B4: M1NUT2 | C4: DPS | D4: Ilios | E4: Control | F4: 10 | G4: 2 | H4: 0 | I4: 6539 | J4: 258 | K4: 313 | L4: 00:07:06 | M4: =L4*86400 -> 426 | N4: {=INDEX('MATCH INFO'!O:O, INT((ROW()-2)/10)+2 + 29)} -> 260612_CB_SB_S1
A5: CB | B5: TENTEN | C5: SPT | D5: Ilios | E5: Control | F5: 6 | G5: 3 | H5: 6 | I5: 2534 | J5: 5358 | K5: 1327 | L5: 00:07:06 | M5: =L5*86400 -> 426 | N5: {=INDEX('MATCH INFO'!O:O, INT((ROW()-2)/10)+2 + 29)} -> 260612_CB_SB_S1
A6: CB | B6: WOOCHAN | C6: SPT | D6: Ilios | E6: Control | F6: 5 | G6: 0 | H6: 8 | I6: 4607 | J6: 6392 | K6: 0 | L6: 00:07:06 | M6: =L6*86400 -> 426 | N6: {=INDEX('MATCH INFO'!O:O, INT((ROW()-2)/10)+2 + 29)} -> 260612_CB_SB_S1
A7: SB | B7: AZENT | C7: DPS | D7: Ilios | E7: Control | F7: 6 | G7: 5 | H7: 0 | I7: 6072 | J7: 133 | K7: 0 | L7: 00:07:06 | M7: =L7*86400 -> 426 | N7: {=INDEX('MATCH INFO'!O:O, INT((ROW()-2)/10)+2 + 29)} -> 260612_CB_SB_S1
A8: SB | B8: DUMBBELL | C8: SPT | D8: Ilios | E8: Control | F8: 3 | G8: 2 | H8: 6 | I8: 5033 | J8: 4993 | K8: 1279 | L8: 00:07:06 | M8: =L8*86400 -> 426 | N8: {=INDEX('MATCH INFO'!O:O, INT((ROW()-2)/10)+2 + 29)} -> 260612_CB_SB_S1
A9: SB | B9: SENTIER | C9: TANK | D9: Ilios | E9: Control | F9: 3 | G9: 3 | H9: 1 | I9: 4170 | J9: 1321 | K9: 3035 | L9: 00:07:06 | M9: =L9*86400 -> 426 | N9: {=INDEX('MATCH INFO'!O:O, INT((ROW()-2)/10)+2 + 29)} -> 260612_CB_SB_S1
A10: SB | B10: SORI | C10: DPS | D10: Ilios | E10: Control | F10: 3 | G10: 7 | H10: 0 | I10: 5562 | J10: 0 | K10: 86 | L10: 00:07:06 | M10: =L10*86400 -> 426 | N10: {=INDEX('MATCH INFO'!O:O, INT((ROW()-2)/10)+2 + 29)} -> 260612_CB_SB_S1
A11: SB | B11: UNIV2R | C11: SPT | D11: Ilios | E11: Control | F11: 4 | G11: 5 | H11: 4 | I11: 4764 | J11: 4943 | K11: 0 | L11: 00:07:06 | M11: =L11*86400 -> 426 | N11: {=INDEX('MATCH INFO'!O:O, INT((ROW()-2)/10)+2 + 29)} -> 260612_CB_SB_S1
A12: SB | B12: DUMBBELL | C12: SPT | D12: New Junk City | E12: Flashpoint | F12: 9 | G12: 6 | H12: 13 | I12: 3278 | J12: 9861 | K12: 1274 | L12: 00:12:19 | M12: =L12*86400 -> 739 | N12: {=INDEX('MATCH INFO'!O:O, INT((ROW()-2)/10)+2 + 29)} -> 260612_CB_SB_S2
A13: SB | B13: HOMERUNBALL | C13: TANK | D13: New Junk City | E13: Flashpoint | F13: 15 | G13: 5 | H13: 7 | I13: 11067 | J13: 0 | K13: 19977 | L13: 00:12:19 | M13: =L13*86400 -> 739 | N13: {=INDEX('MATCH INFO'!O:O, INT((ROW()-2)/10)+2 + 29)} -> 260612_CB_SB_S2
... A291: FLC | B291: SP1NT | C291: DPS | D291: New Junk City | E291: Flashpoint | F291: 11 | G291: 8 | H291: 0 | I291: 5798 | J291: 615 | K291: 0 | L291: 00:07:27 | M291: =L291*86400 -> 447 | N291: {=INDEX('MATCH INFO'!O:O, INT((ROW()-2)/10)+2 + 29)} -> 260614_FLC_T1_S5

Sheet MATCH_W3
A1: Team | B1: Player | C1: Position | D1: Map | E1: Map Type | F1: Elim | G1: Death | H1: Assists | I1: Damage | J1: Heal | K1: Mitigated | L1: Playtime | M1: Playtime(Seconds) | N1: MATCH_ID
A2: ROZE | B2: BECKY | C2: DPS | D2: Ilios | E2: Control | F2: 30 | G2: 7 | H2: 6 | I2: 14489 | J2: 455 | K2: 660 | L2: 00:13:52 | M2: =L2*86400 -> 832 | N2: {=INDEX('MATCH INFO'!O:O, INT((ROW()-2)/10)+2 + 29+29)} -> 260619_ROZE_CB_S1
A3: ROZE | B3: HEISER | C3: TANK | D3: Ilios | E3: Control | F3: 29 | G3: 4 | H3: 9 | I3: 10005 | J3: 1867 | K3: 7876 | L3: 00:13:52 | M3: =L3*86400 -> 832 | N3: {=INDEX('MATCH INFO'!O:O, INT((ROW()-2)/10)+2 + 29+29)} -> 260619_ROZE_CB_S1
A4: ROZE | B4: IRONY | C4: SPT | D4: Ilios | E4: Control | F4: 17 | G4: 7 | H4: 24 | I4: 8525 | J4: 7263 | K4: 512 | L4: 00:13:52 | M4: =L4*86400 -> 832 | N4: {=INDEX('MATCH INFO'!O:O, INT((ROW()-2)/10)+2 + 29+29)} -> 260619_ROZE_CB_S1
A5: ROZE | B5: KILO | C5: DPS | D5: Ilios | E5: Control | F5: 26 | G5: 10 | H5: 3 | I5: 13794 | J5: 0 | K5: 860 | L5: 00:13:52 | M5: =L5*86400 -> 832 | N5: {=INDEX('MATCH INFO'!O:O, INT((ROW()-2)/10)+2 + 29+29)} -> 260619_ROZE_CB_S1
A6: ROZE | B6: OPENER | C6: SPT | D6: Ilios | E6: Control | F6: 15 | G6: 5 | H6: 20 | I6: 2695 | J6: 10386 | K6: 0 | L6: 00:13:52 | M6: =L6*86400 -> 832 | N6: {=INDEX('MATCH INFO'!O:O, INT((ROW()-2)/10)+2 + 29+29)} -> 260619_ROZE_CB_S1
A7: CB | B7: ARGON | C7: DPS | D7: Ilios | E7: Control | F7: 18 | G7: 9 | H7: 3 | I7: 12526 | J7: 0 | K7: 503 | L7: 00:13:52 | M7: =L7*86400 -> 832 | N7: {=INDEX('MATCH INFO'!O:O, INT((ROW()-2)/10)+2 + 29+29)} -> 260619_ROZE_CB_S1
A8: CB | B8: FARMER | C8: TANK | D8: Ilios | E8: Control | F8: 13 | G8: 9 | H8: 0 | I8: 9539 | J8: 5685 | K8: 2066 | L8: 00:13:52 | M8: =L8*86400 -> 832 | N8: {=INDEX('MATCH INFO'!O:O, INT((ROW()-2)/10)+2 + 29+29)} -> 260619_ROZE_CB_S1
A9: CB | B9: M1NUT2 | C9: DPS | D9: Ilios | E9: Control | F9: 20 | G9: 12 | H9: 1 | I9: 13718 | J9: 0 | K9: 418 | L9: 00:13:52 | M9: =L9*86400 -> 832 | N9: {=INDEX('MATCH INFO'!O:O, INT((ROW()-2)/10)+2 + 29+29)} -> 260619_ROZE_CB_S1
A10: CB | B10: TENTEN | C10: SPT | D10: Ilios | E10: Control | F10: 15 | G10: 8 | H10: 19 | I10: 5087 | J10: 10222 | K10: 2500 | L10: 00:13:52 | M10: =L10*86400 -> 832 | N10: {=INDEX('MATCH INFO'!O:O, INT((ROW()-2)/10)+2 + 29+29)} -> 260619_ROZE_CB_S1
A11: CB | B11: WOOCHAN | C11: SPT | D11: Ilios | E11: Control | F11: 7 | G11: 7 | H11: 20 | I11: 4741 | J11: 11599 | K11: 0 | L11: 00:13:52 | M11: =L11*86400 -> 832 | N11: {=INDEX('MATCH INFO'!O:O, INT((ROW()-2)/10)+2 + 29+29)} -> 260619_ROZE_CB_S1
A12: ROZE | B12: BECKY | C12: DPS | D12: Circuit Royal | E12: Escort | F12: 21 | G12: 11 | H12: 5 | I12: 21199 | J12: 91 | K12: 198 | L12: 00:18:53 | M12: =L12*86400 -> 1133 | N12: {=INDEX('MATCH INFO'!O:O, INT((ROW()-2)/10)+2 + 29+29)} -> 260619_ROZE_CB_S2
A13: ROZE | B13: IRONY | C13: SPT | D13: Circuit Royal | E13: Escort | F13: 11 | G13: 6 | H13: 22 | I13: 5148 | J13: 29534 | K13: 0 | L13: 00:18:53 | M13: =L13*86400 -> 1133 | N13: {=INDEX('MATCH INFO'!O:O, INT((ROW()-2)/10)+2 + 29+29)} -> 260619_ROZE_CB_S2
... A341: ZETA | B341: VIOL2T | C341: SPT | D341: Runasapi | E341: Push | F341: 16 | G341: 4 | H341: 17 | I341: 2727 | J341: 2754 | K341: 1086 | L341: 00:05:47 | M341: =L341*86400 -> 347 | N341: {=INDEX('MATCH INFO'!O:O, INT((ROW()-2)/10)+2 + 29+29)} -> 260621_ZETA_PF_S3

Sheet MATCH_W4
A1: Team | B1: Player | C1: Position | D1: Map | E1: Map Type | F1: Elim | G1: Death | H1: Assists | I1: Damage | J1: Heal | K1: Mitigated | L1: Playtime | M1: Playtime(Seconds) | N1: MATCH_ID
A2: CB | B2: ARGON | C2: DPS | D2: Antarctic Peninsula | E2: Control | F2: 26 | G2: 7 | H2: 0 | I2: 16694 | J2: 2408 | K2: 0 | L2: 00:11:18 | M2: =L2*86400 -> 678 | N2: {=INDEX('MATCH INFO'!O:O, INT((ROW()-2)/10)+2 + 92)} -> 260626_CB_O2_S1
A3: CB | B3: GUR3UM | C3: TANK | D3: Antarctic Peninsula | E3: Control | F3: 24 | G3: 9 | H3: 15 | I3: 17799 | J3: 4725 | K3: 9927 | L3: 00:11:18 | M3: =L3*86400 -> 678 | N3: {=INDEX('MATCH INFO'!O:O, INT((ROW()-2)/10)+2 + 92)} -> 260626_CB_O2_S1
A4: CB | B4: M1NUT2 | C4: DPS | D4: Antarctic Peninsula | E4: Control | F4: 23 | G4: 8 | H4: 2 | I4: 13842 | J4: 53 | K4: 583 | L4: 00:11:18 | M4: =L4*86400 -> 678 | N4: {=INDEX('MATCH INFO'!O:O, INT((ROW()-2)/10)+2 + 92)} -> 260626_CB_O2_S1
A5: CB | B5: TENTEN | C5: SPT | D5: Antarctic Peninsula | E5: Control | F5: 13 | G5: 10 | H5: 13 | I5: 5915 | J5: 9261 | K5: 1478 | L5: 00:11:18 | M5: =L5*86400 -> 678 | N5: {=INDEX('MATCH INFO'!O:O, INT((ROW()-2)/10)+2 + 92)} -> 260626_CB_O2_S1
A6: CB | B6: WOOCHAN | C6: SPT | D6: Antarctic Peninsula | E6: Control | F6: 15 | G6: 7 | H6: 25 | I6: 7162 | J6: 19573 | K6: 0 | L6: 00:11:18 | M6: =L6*86400 -> 678 | N6: {=INDEX('MATCH INFO'!O:O, INT((ROW()-2)/10)+2 + 92)} -> 260626_CB_O2_S1
A7: O2 | B7: FAITH | C7: SPT | D7: Antarctic Peninsula | E7: Control | F7: 24 | G7: 7 | H7: 22 | I7: 6497 | J7: 10324 | K7: 2337 | L7: 00:11:18 | M7: =L7*86400 -> 678 | N7: {=INDEX('MATCH INFO'!O:O, INT((ROW()-2)/10)+2 + 92)} -> 260626_CB_O2_S1
A8: O2 | B8: FATE | C8: TANK | D8: Antarctic Peninsula | E8: Control | F8: 34 | G8: 9 | H8: 20 | I8: 17468 | J8: 4174 | K8: 6792 | L8: 00:11:18 | M8: =L8*86400 -> 678 | N8: {=INDEX('MATCH INFO'!O:O, INT((ROW()-2)/10)+2 + 92)} -> 260626_CB_O2_S1
A9: O2 | B9: GAMJUNG | C9: SPT | D9: Antarctic Peninsula | E9: Control | F9: 22 | G9: 4 | H9: 33 | I9: 8266 | J9: 22785 | K9: 0 | L9: 00:11:18 | M9: =L9*86400 -> 678 | N9: {=INDEX('MATCH INFO'!O:O, INT((ROW()-2)/10)+2 + 92)} -> 260626_CB_O2_S1
A10: O2 | B10: PERR | C10: DPS | D10: Antarctic Peninsula | E10: Control | F10: 29 | G10: 3 | H10: 7 | I10: 14652 | J10: 0 | K10: 383 | L10: 00:11:18 | M10: =L10*86400 -> 678 | N10: {=INDEX('MATCH INFO'!O:O, INT((ROW()-2)/10)+2 + 92)} -> 260626_CB_O2_S1
A11: O2 | B11: WUTIAN | C11: DPS | D11: Antarctic Peninsula | E11: Control | F11: 29 | G11: 8 | H11: 0 | I11: 12656 | J11: 1942 | K11: 0 | L11: 00:11:18 | M11: =L11*86400 -> 678 | N11: {=INDEX('MATCH INFO'!O:O, INT((ROW()-2)/10)+2 + 92)} -> 260626_CB_O2_S1
A12: CB | B12: ARGON | C12: DPS | D12: King's Row | E12: Hybrid | F12: 20 | G12: 9 | H12: 2 | I12: 8848 | J12: 553 | K12: 2098 | L12: 00:15:22 | M12: =L12*86400 -> 922 | N12: {=INDEX('MATCH INFO'!O:O, INT((ROW()-2)/10)+2 + 92)} -> 260626_CB_O2_S2
A13: CB | B13: GUR3UM | C13: TANK | D13: King's Row | E13: Hybrid | F13: 11 | G13: 8 | H13: 1 | I13: 15673 | J13: 0 | K13: 33071 | L13: 00:15:22 | M13: =L13*86400 -> 922 | N13: {=INDEX('MATCH INFO'!O:O, INT((ROW()-2)/10)+2 + 92)} -> 260626_CB_O2_S2
... A321: ZETA | B321: VIOL2T | C321: SPT | D321: Runasapi | E321: Push | F321: 25 | G321: 5 | H321: 31 | I321: 3569 | J321: 10494 | K321: 0 | L321: 00:11:02 | M321: =L321*86400 -> 662 | N321: {=INDEX('MATCH INFO'!O:O, INT((ROW()-2)/10)+2 + 92)} -> 260628_CR_ZETA_S5

Sheet MATCH_W5
A1: Team | B1: Player | C1: Position | D1: Map | E1: Map Type | F1: Elim | G1: Death | H1: Assists | I1: Damage | J1: Heal | K1: Mitigated | L1: Playtime | M1: Playtime(Seconds) | N1: MATCH_ID
A2: O2 | B2: FAITH | C2: SPT | D2: Antarctic Peninsula | E2: Control | F2: 5 | G2: 6 | H2: 5 | I2: 2828 | J2: 3483 | K2: 923 | L2: 00:06:11 | M2: =L2*86400 -> 371 | N2: {=INDEX('MATCH INFO'!O:O, INT((ROW()-2)/10)+2 + 124)} -> 260703_O2_ROZE_S1
A3: O2 | B3: GAMJUNG | C3: SPT | D3: Antarctic Peninsula | E3: Control | F3: 5 | G3: 8 | H3: 6 | I3: 2979 | J3: 6397 | K3: 0 | L3: 00:06:11 | M3: =L3*86400 -> 371 | N3: {=INDEX('MATCH INFO'!O:O, INT((ROW()-2)/10)+2 + 124)} -> 260703_O2_ROZE_S1
A4: O2 | B4: PERR | C4: DPS | D4: Antarctic Peninsula | E4: Control | F4: 7 | G4: 7 | H4: 3 | I4: 6306 | J4: 75 | K4: 266 | L4: 00:06:11 | M4: =L4*86400 -> 371 | N4: {=INDEX('MATCH INFO'!O:O, INT((ROW()-2)/10)+2 + 124)} -> 260703_O2_ROZE_S1
A5: O2 | B5: SEUNGAN | C5: TANK | D5: Antarctic Peninsula | E5: Control | F5: 7 | G5: 9 | H5: 6 | I5: 7160 | J5: 1656 | K5: 4261 | L5: 00:06:11 | M5: =L5*86400 -> 371 | N5: {=INDEX('MATCH INFO'!O:O, INT((ROW()-2)/10)+2 + 124)} -> 260703_O2_ROZE_S1
A6: O2 | B6: WUTIAN | C6: DPS | D6: Antarctic Peninsula | E6: Control | F6: 5 | G6: 9 | H6: 0 | I6: 8698 | J6: 1161 | K6: 0 | L6: 00:06:11 | M6: =L6*86400 -> 371 | N6: {=INDEX('MATCH INFO'!O:O, INT((ROW()-2)/10)+2 + 124)} -> 260703_O2_ROZE_S1
A7: ROZE | B7: BECKY | C7: DPS | D7: Antarctic Peninsula | E7: Control | F7: 32 | G7: 0 | H7: 0 | I7: 8104 | J7: 1262 | K7: 0 | L7: 00:06:11 | M7: =L7*86400 -> 371 | N7: {=INDEX('MATCH INFO'!O:O, INT((ROW()-2)/10)+2 + 124)} -> 260703_O2_ROZE_S1
A8: ROZE | B8: HEISER | C8: TANK | D8: Antarctic Peninsula | E8: Control | F8: 32 | G8: 2 | H8: 19 | I8: 9195 | J8: 3001 | K8: 3690 | L8: 00:06:11 | M8: =L8*86400 -> 371 | N8: {=INDEX('MATCH INFO'!O:O, INT((ROW()-2)/10)+2 + 124)} -> 260703_O2_ROZE_S1
A9: ROZE | B9: IRONY | C9: SPT | D9: Antarctic Peninsula | E9: Control | F9: 17 | G9: 0 | H9: 31 | I9: 2982 | J9: 10786 | K9: 0 | L9: 00:06:11 | M9: =L9*86400 -> 371 | N9: {=INDEX('MATCH INFO'!O:O, INT((ROW()-2)/10)+2 + 124)} -> 260703_O2_ROZE_S1
A10: ROZE | B10: OPENER | C10: SPT | D10: Antarctic Peninsula | E10: Control | F10: 19 | G10: 2 | H10: 15 | I10: 3061 | J10: 4596 | K10: 2066 | L10: 00:06:11 | M10: =L10*86400 -> 371 | N10: {=INDEX('MATCH INFO'!O:O, INT((ROW()-2)/10)+2 + 124)} -> 260703_O2_ROZE_S1
A11: ROZE | B11: PROBE | C11: DPS | D11: Antarctic Peninsula | E11: Control | F11: 26 | G11: 3 | H11: 4 | I11: 7017 | J11: 0 | K11: 210 | L11: 00:06:11 | M11: =L11*86400 -> 371 | N11: {=INDEX('MATCH INFO'!O:O, INT((ROW()-2)/10)+2 + 124)} -> 260703_O2_ROZE_S1
A12: O2 | B12: FAITH | C12: SPT | D12: King's Row | E12: Hybrid | F12: 23 | G12: 9 | H12: 9 | I12: 6444 | J12: 10763 | K12: 0 | L12: 00:16:20 | M12: =L12*86400 -> 980 | N12: {=INDEX('MATCH INFO'!O:O, INT((ROW()-2)/10)+2 + 124)} -> 260703_O2_ROZE_S2
A13: O2 | B13: GAMJUNG | C13: SPT | D13: King's Row | E13: Hybrid | F13: 13 | G13: 12 | H13: 28 | I13: 8511 | J13: 14122 | K13: 0 | L13: 00:16:20 | M13: =L13*86400 -> 980 | N13: {=INDEX('MATCH INFO'!O:O, INT((ROW()-2)/10)+2 + 124)} -> 260703_O2_ROZE_S2
... A331: T1 | B331: ZEST | C331: DPS | D331: Colosseo | E331: Push | F331: 16 | G331: 3 | H331: 1 | I331: 6967 | J331: 225 | K331: 336 | L331: 00:06:33 | M331: =L331*86400 -> 393 | N331: {=INDEX('MATCH INFO'!O:O, INT((ROW()-2)/10)+2 + 124)} -> 260705_T1_FLC_S3

Sheet MATCH_W6
A1: Team | B1: Player | C1: Position | D1: Map | E1: Map Type | F1: Elim | G1: Death | H1: Assists | I1: Damage | J1: Heal | K1: Mitigated | L1: Playtime | M1: Playtime(Seconds) | N1: MATCH_ID
A2: FLC | B2: CHECKMATE | C2: DPS | D2: Antarctic Peninsula | E2: Control | F2: 21 | G2: 6 | H2: 3 | I2: 10423 | J2: 482 | K2: 1317 | L2: 00:11:58 | M2: =L2*86400 -> 718 | N2: {=INDEX('MATCH INFO'!O:O, INT((ROW()-2)/10)+2 + 157)} -> 260710_FLC_ROZE_S1
A3: FLC | B3: CHIYO | C3: SPT | D3: Antarctic Peninsula | E3: Control | F3: 10 | G3: 10 | H3: 17 | I3: 6807 | J3: 9586 | K3: 2298 | L3: 00:11:58 | M3: =L3*86400 -> 718 | N3: {=INDEX('MATCH INFO'!O:O, INT((ROW()-2)/10)+2 + 157)} -> 260710_FLC_ROZE_S1
A4: FLC | B4: FIELDER | C4: SPT | D4: Antarctic Peninsula | E4: Control | F4: 10 | G4: 8 | H4: 20 | I4: 5888 | J4: 16754 | K4: 0 | L4: 00:11:58 | M4: =L4*86400 -> 718 | N4: {=INDEX('MATCH INFO'!O:O, INT((ROW()-2)/10)+2 + 157)} -> 260710_FLC_ROZE_S1
A5: FLC | B5: HANBIN | C5: TANK | D5: Antarctic Peninsula | E5: Control | F5: 19 | G5: 11 | H5: 11 | I5: 18073 | J5: 5137 | K5: 11000 | L5: 00:11:58 | M5: =L5*86400 -> 718 | N5: {=INDEX('MATCH INFO'!O:O, INT((ROW()-2)/10)+2 + 157)} -> 260710_FLC_ROZE_S1
A6: FLC | B6: SP1NT | C6: DPS | D6: Antarctic Peninsula | E6: Control | F6: 15 | G6: 9 | H6: 1 | I6: 12355 | J6: 0 | K6: 613 | L6: 00:11:58 | M6: =L6*86400 -> 718 | N6: {=INDEX('MATCH INFO'!O:O, INT((ROW()-2)/10)+2 + 157)} -> 260710_FLC_ROZE_S1
A7: ROZE | B7: BECKY | C7: DPS | D7: Antarctic Peninsula | E7: Control | F7: 27 | G7: 7 | H7: 5 | I7: 10591 | J7: 380 | K7: 1449 | L7: 00:11:58 | M7: =L7*86400 -> 718 | N7: {=INDEX('MATCH INFO'!O:O, INT((ROW()-2)/10)+2 + 157)} -> 260710_FLC_ROZE_S1
A8: ROZE | B8: HEISER | C8: TANK | D8: Antarctic Peninsula | E8: Control | F8: 31 | G8: 4 | H8: 15 | I8: 20571 | J8: 4407 | K8: 8541 | L8: 00:11:58 | M8: =L8*86400 -> 718 | N8: {=INDEX('MATCH INFO'!O:O, INT((ROW()-2)/10)+2 + 157)} -> 260710_FLC_ROZE_S1
A9: ROZE | B9: IRONY | C9: SPT | D9: Antarctic Peninsula | E9: Control | F9: 12 | G9: 7 | H9: 27 | I9: 6074 | J9: 18170 | K9: 0 | L9: 00:11:58 | M9: =L9*86400 -> 718 | N9: {=INDEX('MATCH INFO'!O:O, INT((ROW()-2)/10)+2 + 157)} -> 260710_FLC_ROZE_S1
A10: ROZE | B10: OPENER | C10: SPT | D10: Antarctic Peninsula | E10: Control | F10: 21 | G10: 6 | H10: 18 | I10: 5705 | J10: 9549 | K10: 1976 | L10: 00:11:58 | M10: =L10*86400 -> 718 | N10: {=INDEX('MATCH INFO'!O:O, INT((ROW()-2)/10)+2 + 157)} -> 260710_FLC_ROZE_S1
A11: ROZE | B11: PROBE | C11: DPS | D11: Antarctic Peninsula | E11: Control | F11: 29 | G11: 7 | H11: 6 | I11: 15909 | J11: 37 | K11: 394 | L11: 00:11:58 | M11: =L11*86400 -> 718 | N11: {=INDEX('MATCH INFO'!O:O, INT((ROW()-2)/10)+2 + 157)} -> 260710_FLC_ROZE_S1
A12: FLC | B12: CHECKMATE | C12: DPS | D12: New Junk City | E12: Flashpoint | F12: 8 | G12: 7 | H12: 0 | I12: 7595 | J12: 1491 | K12: 0 | L12: 00:09:04 | M12: =L12*86400 -> 544 | N12: {=INDEX('MATCH INFO'!O:O, INT((ROW()-2)/10)+2 + 157)} -> 260710_FLC_ROZE_S2
A13: FLC | B13: CHIYO | C13: SPT | D13: New Junk City | E13: Flashpoint | F13: 11 | G13: 7 | H13: 10 | I13: 5013 | J13: 6265 | K13: 1618 | L13: 00:09:04 | M13: =L13*86400 -> 544 | N13: {=INDEX('MATCH INFO'!O:O, INT((ROW()-2)/10)+2 + 157)} -> 260710_FLC_ROZE_S2
... A311: CR | B311: VIGILANTE | C311: SPT | D311: Neon Junction | E311: Hybrid | F311: 25 | G311: 12 | H311: 53 | I311: 6492 | J311: 27804 | K311: 0 | L311: 00:20:57 | M311: =L311*86400 -> 1257 | N311: {=INDEX('MATCH INFO'!O:O, INT((ROW()-2)/10)+2 + 157)} -> 260712_CR_ZETA_S6

Sheet TOTAL STATISTICS
A1: TEAM | B1: PLAYER | C1: POSITION | D1: TOTAL ELIMS | E1: TOTAL DEATHS | F1: TOTAL ASSISTS | G1: TOTAL DAMAGE | H1: TOTAL HEAL | I1: TOTAL MITIGATED | J1: TOTAL E/D | K1: TOTAL PLAYTIME
A2: O2 | B2: FATE | C2: TANK | D2: =SUMIF(MATCH_W1!$B:$B,$B2,MATCH_W1!$F:$F)+SUMIF(MATCH_W2!$B:$B,$B2,MATCH_W2!$F:$F)+SUMIF(MATCH_W3!$B:$B,$B2,MATCH_W3!$F:$F)+SUMIF(MATCH_W4!$B:$B,$B2,MATCH_W4!$F:$F)+SUMIF(MATCH_W5!$B:$B,$B2,MATCH_W5!$F:$F)+SUMIF(MATCH_W6!$B:$B,$B2,MATCH_W6!$F:$F) -> 349 | E2: =SUMIF(MATCH_W1!$B:$B,$B2,MATCH_W1!$G:$G)+SUMIF(MATCH_W2!$B:$B,$B2,MATCH_W2!$G:$G)+SUMIF(MATCH_W3!$B:$B,$B2,MATCH_W3!$G:$G)+SUMIF(MATCH_W4!$B:$B,$B2,MATCH_W4!$G:$G)+SUMIF(MATCH_W5!$B:$B,$B2,MATCH_W5!$G:$G)+SUMIF(MATCH_W6!$B:$B,$B2,MATCH_W6!$G:$G) -> 120 | F2: =SUMIF(MATCH_W1!$B:$B,$B2,MATCH_W1!$H:$H)+SUMIF(MATCH_W2!$B:$B,$B2,MATCH_W2!$H:$H)+SUMIF(MATCH_W3!$B:$B,$B2,MATCH_W3!$H:$H)+SUMIF(MATCH_W4!$B:$B,$B2,MATCH_W4!$H:$H)+SUMIF(MATCH_W5!$B:$B,$B2,MATCH_W5!$H:$H)+SUMIF(MATCH_W6!$B:$B,$B2,MATCH_W6!$H:$H) -> 213 | G2: =SUMIF(MATCH_W1!$B:$B,$B2,MATCH_W1!$I:$I)+SUMIF(MATCH_W2!$B:$B,$B2,MATCH_W2!$I:$I)+SUMIF(MATCH_W3!$B:$B,$B2,MATCH_W3!$I:$I)+SUMIF(MATCH_W4!$B:$B,$B2,MATCH_W4!$I:$I)+SUMIF(MATCH_W5!$B:$B,$B2,MATCH_W5!$I:$I)+SUMIF(MATCH_W6!$B:$B,$B2,MATCH_W6!$I:$I) -> 220283 | H2: =SUMIF(MATCH_W1!$B:$B,$B2,MATCH_W1!$J:$J)+SUMIF(MATCH_W2!$B:$B,$B2,MATCH_W2!$J:$J)+SUMIF(MATCH_W3!$B:$B,$B2,MATCH_W3!$J:$J)+SUMIF(MATCH_W4!$B:$B,$B2,MATCH_W4!$J:$J)+SUMIF(MATCH_W5!$B:$B,$B2,MATCH_W5!$J:$J)+SUMIF(MATCH_W6!$B:$B,$B2,MATCH_W6!$J:$J) -> 51331 | I2: =SUMIF(MATCH_W1!$B:$B,$B2,MATCH_W1!$K:$K)+SUMIF(MATCH_W2!$B:$B,$B2,MATCH_W2!$K:$K)+SUMIF(MATCH_W3!$B:$B,$B2,MATCH_W3!$K:$K)+SUMIF(MATCH_W4!$B:$B,$B2,MATCH_W4!$K:$K)+SUMIF(MATCH_W5!$B:$B,$B2,MATCH_W5!$K:$K)+SUMIF(MATCH_W6!$B:$B,$B2,MATCH_W6!$K:$K) -> 128806 | J2: =IFERROR(D2/E2,0) -> 2.9083333 | K2: =SUMIF(MATCH_W1!$B:$B,$B2,MATCH_W1!$M:$M)+SUMIF(MATCH_W2!$B:$B,$B2,MATCH_W2!$M:$M)+SUMIF(MATCH_W3!$B:$B,$B2,MATCH_W3!$M:$M)+SUMIF(MATCH_W4!$B:$B,$B2,MATCH_W4!$M:$M)+SUMIF(MATCH_W5!$B:$B,$B2,MATCH_W5!$M:$M)+SUMIF(MATCH_W6!$B:$B,$B2,MATCH_W6!$M:$M) -> 10770
